Workbook

Sheet Read Me
A1: Destination Pet: business case for a connected-care data platform
A2: Prepared as a portfolio exercise by Chris Lavelle, from public information only. Not affiliated with or reviewed by Destination Pet.
A4: The question
A5: What is a data and analytics platform worth to Destination Pet, given that it owns every location and therefore its own data?
A7: How ownership changes the case
A8: 1. No partner incentives: the largest variable cost in the partner-network version of this model disappears.
A9: 2. Most value is internal: staffing, cross-selling across Connected Care services, and clinical quality, which raise EBITDA directly and therefore exit value.
A10: 3. External data sales are possible but gated by scale; some products (rare drug-safety studies) need far more veterinary volume than one company has.
A11: 4. New costs appear instead: unifying systems across acquired brands, and consent and privacy work.
A13: How to use
A14: Edit blue cells on the Assumptions sheet. Peach cells are company facts to confirm with Destination Pet finance and operations. Yellow cells are the key levers.
A15: The Summary sheet shows all three scenarios; the Model sheet shows the year-by-year build.
... A18: Operating inputs (labor cost, customers and patients per location, prices, the number of veterinary locations) are ILLUSTRATIVE PLACEHOLDERS. Effect sizes from TailSignal come from simulated data and carry a realization haircut. Replace inputs with company data before any decision.

Sheet Summary
A1: Summary by scenario
A2: Placeholders drive these results; see Read Me.
A4: Measure | B4: Low | C4: Base | D4: High
A5: Internal value, Year 5 (EBITDA) | B5: =Model!F14 -> 2316400 | C5: =Model!F40 -> 4632800 | D5: =Model!F66 -> 6485920
A6: External data revenue, Year 5 | B6: =Model!F19 -> 768000 | C6: =Model!F45 -> 960000 | D6: =Model!F71 -> 1104000
A7: Platform cost, Year 5 | B7: =Model!F25 -> 2796000 | C7: =Model!F51 -> 2796000 | D7: =Model!F77 -> 2796000
A8: Net EBITDA impact, Year 5 | B8: =Model!F26 -> 288400 | C8: =Model!F52 -> 2796800 | D8: =Model!F78 -> 4793920
A9: Cumulative net impact, Years 1-5 | B9: =Model!F27 -> -3184600 | C9: =Model!F53 -> 5458800 | D9: =Model!F79 -> 12346720
A10: Enterprise value from Year-5 net impact (x exit multiple) | B10: =MAX(0,Model!F26)*Assumptions!$B$62 -> 3460800 | C10: =MAX(0,Model!F52)*Assumptions!$B$62 -> 33561600 | D10: =MAX(0,Model!F78)*Assumptions!$B$62 -> 57527040
A11: Payback year (cumulative impact turns positive) | B11: =IF(MIN(Model!B28:F28)=99,"Not within 5 years","Year "&MIN(Model!B28:F28)) -> Not within 5 years | C11: =IF(MIN(Model!B54:F54)=99,"Not within 5 years","Year "&MIN(Model!B54:F54)) -> Year 3 | D11: =IF(MIN(Model!B80:F80)=99,"Not within 5 years","Year "&MIN(Model!B80:F80)) -> Year 2
A13: Where Year-5 value comes from (Base) | B13: Amount ($) | C13: Share of gross value
A14: Staffing savings | B14: =Model!F36 -> 3920000 | C14: =IF(SUM($B$14:$B$21)=0,0,B14/SUM($B$14:$B$21)) -> 0.70090116
A15: Connected Care cross-sell | B15: =Model!F37 -> 460800 | C15: =IF(SUM($B$14:$B$21)=0,0,B15/SUM($B$14:$B$21)) -> 0.082391646
A16: Dental capture | B16: =Model!F38 -> 252000 | C16: =IF(SUM($B$14:$B$21)=0,0,B16/SUM($B$14:$B$21)) -> 0.045057932
A17: Membership retention | B17: =Model!F39 -> 0 | C17: =IF(SUM($B$14:$B$21)=0,0,B17/SUM($B$14:$B$21)) -> 0
A18: Data licenses | B18: =Model!F41 -> 720000 | C18: =IF(SUM($B$14:$B$21)=0,0,B18/SUM($B$14:$B$21)) -> 0.12873695
A19: Research reports | B19: =Model!F42 -> 240000 | C19: =IF(SUM($B$14:$B$21)=0,0,B19/SUM($B$14:$B$21)) -> 0.042912316
A20: Common side-effect studies | B20: =Model!F43 -> 0 | C20: =IF(SUM($B$14:$B$21)=0,0,B20/SUM($B$14:$B$21)) -> 0
A21: Rare side-effect studies | B21: =Model!F44 -> 0 | C21: =IF(SUM($B$14:$B$21)=0,0,B21/SUM($B$14:$B$21)) -> 0

Sheet Scale Gates
A1: What one owned network can and cannot unlock
A3: Capability | B3: Needs | C3: Year reached (Base) | D3: Base, Year 5 | F3: Implication
A4: Data licenses (pets observed per year) | B4: =Assumptions!$B$37 -> 100000 | C4: =IF(Model!B34>=$B4,"Year 1",IF(Model!C34>=$B4,"Year 2",IF(Model!D34>=$B4,"Year 3",IF(Model!E34>=$B4,"Year 4",IF(Model!F34>=$B4,"Year 5","Not in 5 years"))))) -> Year 2 | D4: =Model!F34 -> 480000 | F4: Reached early: owning every channel gives volume quickly
A5: Common side-effect studies (dog records, 4 yrs) | B5: =Assumptions!$B$40 -> 792000 | C5: =IF(Model!B35>=$B5,"Year 1",IF(Model!C35>=$B5,"Year 2",IF(Model!D35>=$B5,"Year 3",IF(Model!E35>=$B5,"Year 4",IF(Model!F35>=$B5,"Year 5","Not in 5 years"))))) -> Not in 5 years | D5: =Model!F35 -> 469000 | F5: Depends on veterinary volume, not resort volume
A6: Rare side-effect studies (dog records, 4 yrs) | B6: =Assumptions!$B$41 -> 1287000 | C6: =IF(Model!B35>=$B6,"Year 1",IF(Model!C35>=$B6,"Year 2",IF(Model!D35>=$B6,"Year 3",IF(Model!E35>=$B6,"Year 4",IF(Model!F35>=$B6,"Year 5","Not in 5 years"))))) -> Not in 5 years | D6: =Model!F35 -> 469000 | F6: Likely needs a research partner or consortium beyond one company

Sheet Company Facts
A1: Fact | B1: Value | C1: Source
A2: Services | B2: Boarding, daycare, grooming, training, veterinary care | C2: https://www.destinationpet.com/about-us/about/
A3: Operating model | B3: Connected Care across services; Yourgi pet app | C3: https://www.destinationpet.com/about-us/about/
A4: Locations | B4: 160+ in more than 31 states (June 2023) | C4: https://www.prnewswire.com/news-releases/destination-pet-strengthens-position-in-the-pet-care-industry-with-pet-palace-acquisition-301856956.html
A5: Acquisition example | B5: Pet Palace: 11 facilities, 500+ employees (June 2023) | C5: Same press release
A6: Owner | B6: LetterOne (acquired November 2019) | C6: https://www.cbinsights.com/company/destination-pet
A7: 2025 performance | B7: Return to full-year profitability; revenue ahead of plan; M&A accretive | C7: https://letterone.com/news-and-insights/2025-year-in-review-l1-health/
A8: Yourgi app | B8: Gross booking value growing >100% a year; became a two-sided marketplace in November 2025 | C8: Same LetterOne review
A9: Not public (confirm) | B9: Number of veterinary locations, revenue and labor cost per location, active pets | C9: Inputs on the Assumptions sheet are placeholders

Sheet Assumptions
A1: Assumptions
A2: Blue = input · peach fill = company fact to confirm · yellow fill = key lever
A4: Scenarios
A5: Scenario | B5: Value effects × | C5: External prices × | G5: Note
A6: Low | B6: 0.5 | C6: 0.8 | G6: Value effects scale every internal benefit; prices scale every external sale
A7: Base | B7: 1 | C7: 1
A8: High | B8: 1.4 | C8: 1.15
A10: Network (company facts to confirm)
A11: Locations (all service types) | B11: 160 | G11: Public: 160+ (June 2023 press release)
A12: Locations with a veterinary clinic | B12: 40 | G12: Not public; placeholder
A13: Unique pets served per location per year | B13: 3000 | G13: Not public; placeholder
A14: Dogs with veterinary records per vet clinic per year | B14: 3500 | G14: Not public; placeholder
A15: Daycare and boarding labor cost per location ($ per year) | B15: 700000 | G15: Not public; placeholder
A16: Share of resort customers not using a company vet | B16: 0.8 | G16: Not public; placeholder
A18: Rollout
A19: Item | B19: Year 1 | C19: Year 2 | D19: Year 3 | E19: Year 4 | F19: Year 5 | G19: Note
A20: Share of locations live on the platform | B20: 0.15 | C20: 0.5 | D20: 0.85 | E20: 1 | F20: 1 | G20: Systems from acquired brands unified over two to three years
A22: Internal value drivers (effects from TailSignal, with a realization haircut)
A23: Driver | B23: Value | G23: Evidence
A24: Daycare staffing cost reduction from demand forecasting | B24: 0.07 | G24: TailSignal backtest, simulated data: 7% lower staffing cost than the seasonal baseline (docs/analytics_results.md)
A25: Realization of simulated effects in practice | B25: 0.5 | G25: Haircut for moving from simulation to operations
A26: Extra conversion of resort customers to company vet care (points) | B26: 0.01 | G26: Assumption: targeted Connected Care offers from daycare, boarding and grooming records
A27: Annual veterinary revenue per new client ($) | B27: 600 | G27: Placeholder
A28: Contribution margin on added veterinary revenue | B28: 0.4 | G28: Placeholder
A29: Extra dental cleanings per vet clinic per year from better charting | B29: 40 | G29: TailSignal: under-charting clinics record 35-43% less dental disease; bring them to the median
A30: Average dental cleaning price ($) | B30: 700 | G30: Placeholder
A31: Contribution margin on dental cleanings | B31: 0.45 | G31: Placeholder
A32: Membership retention benefit per location ($ per year) | B32: 0 | G32: TailSignal reminder-targeting pilot was inconclusive; set to zero until a larger pilot proves it
A34: External data revenue (illustrative prices)
A35: Item | B35: Value | G35: Basis
A36: Data-license annual contract value ($) | B36: 120000 | G36: De-identified cohort, Pet Health Index, service benchmarks
A37: Pets observed per year needed before licensing | B37: 100000 | G37: Privacy: 8% of pets suppressed at ~12,700 pets; assume ~8x that for clean releases
A38: Research report average price ($) | B38: 40000 | G38: Pet food, dental-care and drug makers
A39: Signal-validation study price ($ per study) | B39: 250000 | G39: Drug-safety study for a manufacturer
A40: Dog records needed for common side-effect studies (4-year window) | B40: 792000 | G40: TailSignal Model A2: ~80x a 9,900-dog network
A41: Dog records needed for rare side-effect studies (4-year window) | B41: 1287000 | G41: TailSignal Model A2: ~130x a 9,900-dog network
A42: Study delivery cost (% of study revenue) | B42: 0.4 | G42: Clinical review and annotation
A44: Volume by year | B44: Year 1 | C44: Year 2 | D44: Year 3 | E44: Year 4 | F44: Year 5 | G44: Note
A45: Data licensees | B45: 0 | C45: 2 | D45: 3 | E45: 5 | F45: 6 | G45: Sold only once the license gate is met
A46: Research reports sold | B46: 1 | C46: 3 | D46: 4 | E46: 5 | F46: 6
...

Sheet Model
A1: Five-year build by scenario ($)
A2: All cells are formulas driven by the Assumptions sheet.
A4: Low scenario
A5: Line | B5: Year 1 | C5: Year 2 | D5: Year 3 | E5: Year 4 | F5: Year 5
A6: Live locations | B6: =ROUND(Assumptions!$B$11*Assumptions!B$20,0) -> 24 | C6: =ROUND(Assumptions!$B$11*Assumptions!C$20,0) -> 80 | D6: =ROUND(Assumptions!$B$11*Assumptions!D$20,0) -> 136 | E6: =ROUND(Assumptions!$B$11*Assumptions!E$20,0) -> 160 | F6: =ROUND(Assumptions!$B$11*Assumptions!F$20,0) -> 160
A7: Live vet clinics | B7: =ROUND(Assumptions!$B$12*Assumptions!B$20,0) -> 6 | C7: =ROUND(Assumptions!$B$12*Assumptions!C$20,0) -> 20 | D7: =ROUND(Assumptions!$B$12*Assumptions!D$20,0) -> 34 | E7: =ROUND(Assumptions!$B$12*Assumptions!E$20,0) -> 40 | F7: =ROUND(Assumptions!$B$12*Assumptions!F$20,0) -> 40
A8: Pets observed per year | B8: =B6*Assumptions!$B$13 -> 72000 | C8: =C6*Assumptions!$B$13 -> 240000 | D8: =D6*Assumptions!$B$13 -> 408000 | E8: =E6*Assumptions!$B$13 -> 480000 | F8: =F6*Assumptions!$B$13 -> 480000
A9: Dog veterinary records, trailing 4 years (study window) | B9: =SUM(B7:B7)*Assumptions!$B$14 -> 21000 | C9: =SUM(B7:C7)*Assumptions!$B$14 -> 91000 | D9: =SUM(B7:D7)*Assumptions!$B$14 -> 210000 | E9: =SUM(B7:E7)*Assumptions!$B$14 -> 350000 | F9: =SUM(C7:F7)*Assumptions!$B$14 -> 469000
A10: Internal: daycare and boarding staffing savings | B10: =B6*Assumptions!$B$15*Assumptions!$B$24*Assumptions!$B$25*Assumptions!$B$6 -> 294000 | C10: =C6*Assumptions!$B$15*Assumptions!$B$24*Assumptions!$B$25*Assumptions!$B$6 -> 980000 | D10: =D6*Assumptions!$B$15*Assumptions!$B$24*Assumptions!$B$25*Assumptions!$B$6 -> 1666000 | E10: =E6*Assumptions!$B$15*Assumptions!$B$24*Assumptions!$B$25*Assumptions!$B$6 -> 1960000 | F10: =F6*Assumptions!$B$15*Assumptions!$B$24*Assumptions!$B$25*Assumptions!$B$6 -> 1960000
A11: Internal: Connected Care cross-sell to vet (contribution) | B11: =B6*Assumptions!$B$13*Assumptions!$B$16*Assumptions!$B$26*Assumptions!$B$27*Assumptions!$B$28*Assumptions!$B$25*Assumptions!$B$6 -> 34560 | C11: =C6*Assumptions!$B$13*Assumptions!$B$16*Assumptions!$B$26*Assumptions!$B$27*Assumptions!$B$28*Assumptions!$B$25*Assumptions!$B$6 -> 115200 | D11: =D6*Assumptions!$B$13*Assumptions!$B$16*Assumptions!$B$26*Assumptions!$B$27*Assumptions!$B$28*Assumptions!$B$25*Assumptions!$B$6 -> 195840 | E11: =E6*Assumptions!$B$13*Assumptions!$B$16*Assumptions!$B$26*Assumptions!$B$27*Assumptions!$B$28*Assumptions!$B$25*Assumptions!$B$6 -> 230400 | F11: =F6*Assumptions!$B$13*Assumptions!$B$16*Assumptions!$B$26*Assumptions!$B$27*Assumptions!$B$28*Assumptions!$B$25*Assumptions!$B$6 -> 230400
A12: Internal: dental capture (contribution) | B12: =B7*Assumptions!$B$29*Assumptions!$B$30*Assumptions!$B$31*Assumptions!$B$25*Assumptions!$B$6 -> 18900 | C12: =C7*Assumptions!$B$29*Assumptions!$B$30*Assumptions!$B$31*Assumptions!$B$25*Assumptions!$B$6 -> 63000 | D12: =D7*Assumptions!$B$29*Assumptions!$B$30*Assumptions!$B$31*Assumptions!$B$25*Assumptions!$B$6 -> 107100 | E12: =E7*Assumptions!$B$29*Assumptions!$B$30*Assumptions!$B$31*Assumptions!$B$25*Assumptions!$B$6 -> 126000 | F12: =F7*Assumptions!$B$29*Assumptions!$B$30*Assumptions!$B$31*Assumptions!$B$25*Assumptions!$B$6 -> 126000
A13: Internal: membership retention | B13: =B6*Assumptions!$B$32*Assumptions!$B$6 -> 0 | C13: =C6*Assumptions!$B$32*Assumptions!$B$6 -> 0 | D13: =D6*Assumptions!$B$32*Assumptions!$B$6 -> 0 | E13: =E6*Assumptions!$B$32*Assumptions!$B$6 -> 0 | F13: =F6*Assumptions!$B$32*Assumptions!$B$6 -> 0
A14: Internal value (EBITDA) | B14: =SUM(B10:B13) -> 347460 | C14: =SUM(C10:C13) -> 1158200 | D14: =SUM(D10:D13) -> 1968940 | E14: =SUM(E10:E13) -> 2316400 | F14: =SUM(F10:F13) -> 2316400
A15: External: data licenses | B15: =IF(B8>=Assumptions!$B$37,Assumptions!B$45*Assumptions!$B$36*Assumptions!$C$6,0) -> 0 | C15: =IF(C8>=Assumptions!$B$37,Assumptions!C$45*Assumptions!$B$36*Assumptions!$C$6,0) -> 192000 | D15: =IF(D8>=Assumptions!$B$37,Assumptions!D$45*Assumptions!$B$36*Assumptions!$C$6,0) -> 288000 | E15: =IF(E8>=Assumptions!$B$37,Assumptions!E$45*Assumptions!$B$36*Assumptions!$C$6,0) -> 480000 | F15: =IF(F8>=Assumptions!$B$37,Assumptions!F$45*Assumptions!$B$36*Assumptions!$C$6,0) -> 576000
A16: External: research reports | B16: =Assumptions!B$46*Assumptions!$B$38*Assumptions!$C$6 -> 32000 | C16: =Assumptions!C$46*Assumptions!$B$38*Assumptions!$C$6 -> 96000 | D16: =Assumptions!D$46*Assumptions!$B$38*Assumptions!$C$6 -> 128000 | E16: =Assumptions!E$46*Assumptions!$B$38*Assumptions!$C$6 -> 160000 | F16: =Assumptions!F$46*Assumptions!$B$38*Assumptions!$C$6 -> 192000
A17: External: common side-effect studies | B17: =IF(B9>=Assumptions!$B$40,Assumptions!B$47*Assumptions!$B$39*Assumptions!$C$6,0) -> 0 | C17: =IF(C9>=Assumptions!$B$40,Assumptions!C$47*Assumptions!$B$39*Assumptions!$C$6,0) -> 0 | D17: =IF(D9>=Assumptions!$B$40,Assumptions!D$47*Assumptions!$B$39*Assumptions!$C$6,0) -> 0 | E17: =IF(E9>=Assumptions!$B$40,Assumptions!E$47*Assumptions!$B$39*Assumptions!$C$6,0) -> 0 | F17: =IF(F9>=Assumptions!$B$40,Assumptions!F$47*Assumptions!$B$39*Assumptions!$C$6,0) -> 0
A18: External: rare side-effect studies | B18: =IF(B9>=Assumptions!$B$41,Assumptions!B$48*Assumptions!$B$39*Assumptions!$C$6,0) -> 0 | C18: =IF(C9>=Assumptions!$B$41,Assumptions!C$48*Assumptions!$B$39*Assumptions!$C$6,0) -> 0 | D18: =IF(D9>=Assumptions!$B$41,Assumptions!D$48*Assumptions!$B$39*Assumptions!$C$6,0) -> 0 | E18: =IF(E9>=Assumptions!$B$41,Assumptions!E$48*Assumptions!$B$39*Assumptions!$C$6,0) -> 0 | F18: =IF(F9>=Assumptions!$B$41,Assumptions!F$48*Assumptions!$B$39*Assumptions!$C$6,0) -> 0
A19: External revenue | B19: =SUM(B15:B18) -> 32000 | C19: =SUM(C15:C18) -> 288000 | D19: =SUM(D15:D18) -> 416000 | E19: =SUM(E15:E18) -> 640000 | F19: =SUM(F15:F18) -> 768000
A20: Data team | B20: =Assumptions!B$59*Assumptions!$B$52 -> 1000000 | C20: =Assumptions!C$59*Assumptions!$B$52 -> 1600000 | D20: =Assumptions!D$59*Assumptions!$B$52 -> 2000000 | E20: =Assumptions!E$59*Assumptions!$B$52 -> 2200000 | F20: =Assumptions!F$59*Assumptions!$B$52 -> 2400000
A21: System integration (one-time, newly live locations) | B21: =B6*Assumptions!$B$53 -> 360000 | C21: =MAX(0,C6-B6)*Assumptions!$B$53 -> 840000 | D21: =MAX(0,D6-C6)*Assumptions!$B$53 -> 840000 | E21: =MAX(0,E6-D6)*Assumptions!$B$53 -> 360000 | F21: =MAX(0,F6-E6)*Assumptions!$B$53 -> 0
A22: Cloud and tooling | B22: =Assumptions!$B$54+B6*Assumptions!$B$55 -> 164400 | C22: =Assumptions!$B$54+C6*Assumptions!$B$55 -> 198000 | D22: =Assumptions!$B$54+D6*Assumptions!$B$55 -> 231600 | E22: =Assumptions!$B$54+E6*Assumptions!$B$55 -> 246000 | F22: =Assumptions!$B$54+F6*Assumptions!$B$55 -> 246000
A23: Privacy, consent and legal | B23: =Assumptions!$B$56 -> 150000 | C23: =Assumptions!$B$56 -> 150000 | D23: =Assumptions!$B$56 -> 150000 | E23: =Assumptions!$B$56 -> 150000 | F23: =Assumptions!$B$56 -> 150000
A24: Study delivery | B24: =(B17+B18)*Assumptions!$B$42 -> 0 | C24: =(C17+C18)*Assumptions!$B$42 -> 0 | D24: =(D17+D18)*Assumptions!$B$42 -> 0 | E24: =(E17+E18)*Assumptions!$B$42 -> 0 | F24: =(F17+F18)*Assumptions!$B$42 -> 0
A25: Total platform cost | B25: =SUM(B20:B24) -> 1674400 | C25: =SUM(C20:C24) -> 2788000 | D25: =SUM(D20:D24) -> 3221600 | E25: =SUM(E20:E24) -> 2956000 | F25: =SUM(F20:F24) -> 2796000
A26: Net EBITDA impact | B26: =B14+B19-B25 -> -1294940 | C26: =C14+C19-C25 -> -1341800 | D26: =D14+D19-D25 -> -836660 | E26: =E14+E19-E25 -> 400 | F26: =F14+F19-F25 -> 288400
A27: Cumulative net impact | B27: =B26 -> -1294940 | C27: =B27+C26 -> -2636740 | D27: =C27+D26 -> -3473400 | E27: =D27+E26 -> -3473000 | F27: =E27+F26 -> -3184600
A28: Helper: year number if cumulative impact positive (else 99) | B28: =IF(B27>0,1,99) -> 99 | C28: =IF(C27>0,2,99) -> 99 | D28: =IF(D27>0,3,99) -> 99 | E28: =IF(E27>0,4,99) -> 99 | F28: =IF(F27>0,5,99) -> 99
A30: Base scenario
A31: Line | B31: Year 1 | C31: Year 2 | D31: Year 3 | E31: Year 4 | F31: Year 5
A32: Live locations | B32: =ROUND(Assumptions!$B$11*Assumptions!B$20,0) -> 24 | C32: =ROUND(Assumptions!$B$11*Assumptions!C$20,0) -> 80 | D32: =ROUND(Assumptions!$B$11*Assumptions!D$20,0) -> 136 | E32: =ROUND(Assumptions!$B$11*Assumptions!E$20,0) -> 160 | F32: =ROUND(Assumptions!$B$11*Assumptions!F$20,0) -> 160
A33: Live vet clinics | B33: =ROUND(Assumptions!$B$12*Assumptions!B$20,0) -> 6 | C33: =ROUND(Assumptions!$B$12*Assumptions!C$20,0) -> 20 | D33: =ROUND(Assumptions!$B$12*Assumptions!D$20,0) -> 34 | E33: =ROUND(Assumptions!$B$12*Assumptions!E$20,0) -> 40 | F33: =ROUND(Assumptions!$B$12*Assumptions!F$20,0) -> 40
A34: Pets observed per year | B34: =B32*Assumptions!$B$13 -> 72000 | C34: =C32*Assumptions!$B$13 -> 240000 | D34: =D32*Assumptions!$B$13 -> 408000 | E34: =E32*Assumptions!$B$13 -> 480000 | F34: =F32*Assumptions!$B$13 -> 480000
A35: Dog veterinary records, trailing 4 years (study window) | B35: =SUM(B33:B33)*Assumptions!$B$14 -> 21000 | C35: =SUM(B33:C33)*Assumptions!$B$14 -> 91000 | D35: =SUM(B33:D33)*Assumptions!$B$14 -> 210000 | E35: =SUM(B33:E33)*Assumptions!$B$14 -> 350000 | F35: =SUM(C33:F33)*Assumptions!$B$14 -> 469000
A36: Internal: daycare and boarding staffing savings | B36: =B32*Assumptions!$B$15*Assumptions!$B$24*Assumptions!$B$25*Assumptions!$B$7 -> 588000 | C36: =C32*Assumptions!$B$15*Assumptions!$B$24*Assumptions!$B$25*Assumptions!$B$7 -> 1960000 | D36: =D32*Assumptions!$B$15*Assumptions!$B$24*Assumptions!$B$25*Assumptions!$B$7 -> 3332000 | E36: =E32*Assumptions!$B$15*Assumptions!$B$24*Assumptions!$B$25*Assumptions!$B$7 -> 3920000 | F36: =F32*Assumptions!$B$15*Assumptions!$B$24*Assumptions!$B$25*Assumptions!$B$7 -> 3920000
A37: Internal: Connected Care cross-sell to vet (contribution) | B37: =B32*Assumptions!$B$13*Assumptions!$B$16*Assumptions!$B$26*Assumptions!$B$27*Assumptions!$B$28*Assumptions!$B$25*Assumptions!$B$7 -> 69120 | C37: =C32*Assumptions!$B$13*Assumptions!$B$16*Assumptions!$B$26*Assumptions!$B$27*Assumptions!$B$28*Assumptions!$B$25*Assumptions!$B$7 -> 230400 | D37: =D32*Assumptions!$B$13*Assumptions!$B$16*Assumptions!$B$26*Assumptions!$B$27*Assumptions!$B$28*Assumptions!$B$25*Assumptions!$B$7 -> 391680 | E37: =E32*Assumptions!$B$13*Assumptions!$B$16*Assumptions!$B$26*Assumptions!$B$27*Assumptions!$B$28*Assumptions!$B$25*Assumptions!$B$7 -> 460800 | F37: =F32*Assumptions!$B$13*Assumptions!$B$16*Assumptions!$B$26*Assumptions!$B$27*Assumptions!$B$28*Assumptions!$B$25*Assumptions!$B$7 -> 460800
A38: Internal: dental capture (contribution) | B38: =B33*Assumptions!$B$29*Assumptions!$B$30*Assumptions!$B$31*Assumptions!$B$25*Assumptions!$B$7 -> 37800 | C38: =C33*Assumptions!$B$29*Assumptions!$B$30*Assumptions!$B$31*Assumptions!$B$25*Assumptions!$B$7 -> 126000 | D38: =D33*Assumptions!$B$29*Assumptions!$B$30*Assumptions!$B$31*Assumptions!$B$25*Assumptions!$B$7 -> 214200 | E38: =E33*Assumptions!$B$29*Assumptions!$B$30*Assumptions!$B$31*Assumptions!$B$25*Assumptions!$B$7 -> 252000 | F38: =F33*Assumptions!$B$29*Assumptions!$B$30*Assumptions!$B$31*Assumptions!$B$25*Assumptions!$B$7 -> 252000
A39: Internal: membership retention | B39: =B32*Assumptions!$B$32*Assumptions!$B$7 -> 0 | C39: =C32*Assumptions!$B$32*Assumptions!$B$7 -> 0 | D39: =D32*Assumptions!$B$32*Assumptions!$B$7 -> 0 | E39: =E32*Assumptions!$B$32*Assumptions!$B$7 -> 0 | F39: =F32*Assumptions!$B$32*Assumptions!$B$7 -> 0
A40: Internal value (EBITDA) | B40: =SUM(B36:B39) -> 694920 | C40: =SUM(C36:C39) -> 2316400 | D40: =SUM(D36:D39) -> 3937880 | E40: =SUM(E36:E39) -> 4632800 | F40: =SUM(F36:F39) -> 4632800
A41: External: data licenses | B41: =IF(B34>=Assumptions!$B$37,Assumptions!B$45*Assumptions!$B$36*Assumptions!$C$7,0) -> 0 | C41: =IF(C34>=Assumptions!$B$37,Assumptions!C$45*Assumptions!$B$36*Assumptions!$C$7,0) -> 240000 | D41: =IF(D34>=Assumptions!$B$37,Assumptions!D$45*Assumptions!$B$36*Assumptions!$C$7,0) -> 360000 | E41: =IF(E34>=Assumptions!$B$37,Assumptions!E$45*Assumptions!$B$36*Assumptions!$C$7,0) -> 600000 | F41: =IF(F34>=Assumptions!$B$37,Assumptions!F$45*Assumptions!$B$36*Assumptions!$C$7,0) -> 720000
A42: External: research reports | B42: =Assumptions!B$46*Assumptions!$B$38*Assumptions!$C$7 -> 40000 | C42: =Assumptions!C$46*Assumptions!$B$38*Assumptions!$C$7 -> 120000 | D42: =Assumptions!D$46*Assumptions!$B$38*Assumptions!$C$7 -> 160000 | E42: =Assumptions!E$46*Assumptions!$B$38*Assumptions!$C$7 -> 200000 | F42: =Assumptions!F$46*Assumptions!$B$38*Assumptions!$C$7 -> 240000
...
