Workbook

Sheet Read Me
A1: TailSignal business case: five-year model
A2: Purpose: size the four monetization models and show when each product unlocks as the partner network grows.
A4: How to use
A5: 1. Edit only blue cells on the Assumptions sheet. Yellow cells are the key levers.
A6: 2. Every other number is a formula. Results for all three scenarios appear on the Summary sheet.
A7: 3. Scale gates (when drug-safety studies become possible) come from the TailSignal analyses, not from guesses.
A9: Legend
A10: Blue text = input you can change. Black text = formula. Green text = link to another sheet. Yellow fill = key assumption.
A12: Important
A13: Prices, adoption rates, headcount and partner ramp are ILLUSTRATIVE ASSUMPTIONS for a portfolio project. Replace them with market quotes and pipeline data before any decision.
A14: Market-context figures are cited on the Assumptions sheet with their sources.

Sheet Summary
A1: Summary by scenario
A2: Illustrative assumptions; see Read Me.
A4: Measure | B4: Low | C4: Base | D4: High
A5: Partner clinics, Year 5 | B5: =Model!F6 -> 900 | C5: =Model!F26 -> 1500 | D5: =Model!F46 -> 1950
A6: Total revenue, Year 5 | B6: =Model!F13 -> 2654400 | C6: =Model!F33 -> 4250000 | D6: =Model!F53 -> 5260100
A7: EBITDA, Year 5 | B7: =Model!F19 -> -1590600 | C7: =Model!F39 -> -885000 | D7: =Model!F59 -> -422400
A8: EBITDA margin, Year 5 | B8: =Model!F20 -> -0.59923146 | C8: =Model!F40 -> -0.20823529 | D8: =Model!F60 -> -0.080302656
A9: Cumulative EBITDA, Years 1-5 | B9: =Model!F21 -> -6865558 | C9: =Model!F41 -> -5141850 | D9: =Model!F61 -> -3958038
A10: First year with positive EBITDA | B10: =IF(MIN(Model!B22:F22)=99,"Not within 5 years","Year "&MIN(Model!B22:F22)) -> Not within 5 years | C10: =IF(MIN(Model!B42:F42)=99,"Not within 5 years","Year "&MIN(Model!B42:F42)) -> Not within 5 years | D10: =IF(MIN(Model!B62:F62)=99,"Not within 5 years","Year "&MIN(Model!B62:F62)) -> Not within 5 years
A11: Revenue per partner clinic, Year 5 | B11: =IF(Model!F6=0,0,Model!F13/Model!F6) -> 2949.3333 | C11: =IF(Model!F26=0,0,Model!F33/Model!F26) -> 2833.3333 | D11: =IF(Model!F46=0,0,Model!F53/Model!F46) -> 2697.4872
A12: Partner incentive per clinic (cost) | B12: =Assumptions!$B$41 -> 1000 | C12: =Assumptions!$B$41 -> 1000 | D12: =Assumptions!$B$41 -> 1000
A13: Extra data licenses needed to break even in Year 5 | B13: =ROUNDUP(MAX(0,-Model!F19)/(Assumptions!$B$25*Assumptions!$C$12),0) -> 17 | C13: =ROUNDUP(MAX(0,-Model!F39)/(Assumptions!$B$25*Assumptions!$C$13),0) -> 8 | D13: =ROUNDUP(MAX(0,-Model!F59)/(Assumptions!$B$25*Assumptions!$C$14),0) -> 4
A15: Revenue mix, Year 5 (Base) | B15: Revenue ($) | C15: Share
A16: Embedded analytics | B16: =Model!F27 -> 1080000 | C16: =IF(SUM($B$16:$B$21)=0,0,B16/SUM($B$16:$B$21)) -> 0.25411765
A17: Research and insights | B17: =Model!F28 -> 400000 | C17: =IF(SUM($B$16:$B$21)=0,0,B17/SUM($B$16:$B$21)) -> 0.094117647
A18: Data products | B18: =Model!F29 -> 960000 | C18: =IF(SUM($B$16:$B$21)=0,0,B18/SUM($B$16:$B$21)) -> 0.22588235
A19: Commercial models | B19: =Model!F30 -> 560000 | C19: =IF(SUM($B$16:$B$21)=0,0,B19/SUM($B$16:$B$21)) -> 0.13176471
A20: Validation studies, common | B20: =Model!F31 -> 750000 | C20: =IF(SUM($B$16:$B$21)=0,0,B20/SUM($B$16:$B$21)) -> 0.17647059
A21: Validation studies, rare | B21: =Model!F32 -> 500000 | C21: =IF(SUM($B$16:$B$21)=0,0,B21/SUM($B$16:$B$21)) -> 0.11764706

Sheet Scale Gates
A1: When each product unlocks
A3: Capability | B3: Clinics needed | C3: Low | D3: Base | E3: High | F3: Evidence
A4: Clinic complication, dental and stewardship scorecards | B4: 9 | C4: =IF(Model!B6>=$B4,"Year 1",IF(Model!C6>=$B4,"Year 2",IF(Model!D6>=$B4,"Year 3",IF(Model!E6>=$B4,"Year 4",IF(Model!F6>=$B4,"Year 5","Later"))))) -> Year 1 | D4: =IF(Model!B26>=$B4,"Year 1",IF(Model!C26>=$B4,"Year 2",IF(Model!D26>=$B4,"Year 3",IF(Model!E26>=$B4,"Year 4",IF(Model!F26>=$B4,"Year 5","Later"))))) -> Year 1 | E4: =IF(Model!B46>=$B4,"Year 1",IF(Model!C46>=$B4,"Year 2",IF(Model!D46>=$B4,"Year 3",IF(Model!E46>=$B4,"Year 4",IF(Model!F46>=$B4,"Year 5","Later"))))) -> Year 1 | F4: Works at today's 9 clinics (docs/clinic_benchmarks_results.md)
A5: Data licenses (privacy-safe granularity) | B5: =Assumptions!$B$26 -> 100 | C5: =IF(Model!B6>=$B5,"Year 1",IF(Model!C6>=$B5,"Year 2",IF(Model!D6>=$B5,"Year 3",IF(Model!E6>=$B5,"Year 4",IF(Model!F6>=$B5,"Year 5","Later"))))) -> Year 3 | D5: =IF(Model!B26>=$B5,"Year 1",IF(Model!C26>=$B5,"Year 2",IF(Model!D26>=$B5,"Year 3",IF(Model!E26>=$B5,"Year 4",IF(Model!F26>=$B5,"Year 5","Later"))))) -> Year 2 | E5: =IF(Model!B46>=$B5,"Year 1",IF(Model!C46>=$B5,"Year 2",IF(Model!D46>=$B5,"Year 3",IF(Model!E46>=$B5,"Year 4",IF(Model!F46>=$B5,"Year 5","Later"))))) -> Year 2 | F5: Assumption; suppression 8% at 9 clinics
A6: Common side-effect validation studies | B6: =Assumptions!$B$29 -> 720 | C6: =IF(Model!B6>=$B6,"Year 1",IF(Model!C6>=$B6,"Year 2",IF(Model!D6>=$B6,"Year 3",IF(Model!E6>=$B6,"Year 4",IF(Model!F6>=$B6,"Year 5","Later"))))) -> Year 5 | D6: =IF(Model!B26>=$B6,"Year 1",IF(Model!C26>=$B6,"Year 2",IF(Model!D26>=$B6,"Year 3",IF(Model!E26>=$B6,"Year 4",IF(Model!F26>=$B6,"Year 5","Later"))))) -> Year 4 | E6: =IF(Model!B46>=$B6,"Year 1",IF(Model!C46>=$B6,"Year 2",IF(Model!D46>=$B6,"Year 3",IF(Model!E46>=$B6,"Year 4",IF(Model!F46>=$B6,"Year 5","Later"))))) -> Year 4 | F6: ~80x today's network (docs/model_a2_results.md)
A7: Rare side-effect validation studies | B7: =Assumptions!$B$30 -> 1170 | C7: =IF(Model!B6>=$B7,"Year 1",IF(Model!C6>=$B7,"Year 2",IF(Model!D6>=$B7,"Year 3",IF(Model!E6>=$B7,"Year 4",IF(Model!F6>=$B7,"Year 5","Later"))))) -> Later | D7: =IF(Model!B26>=$B7,"Year 1",IF(Model!C26>=$B7,"Year 2",IF(Model!D26>=$B7,"Year 3",IF(Model!E26>=$B7,"Year 4",IF(Model!F26>=$B7,"Year 5","Later"))))) -> Year 5 | E7: =IF(Model!B46>=$B7,"Year 1",IF(Model!C46>=$B7,"Year 2",IF(Model!D46>=$B7,"Year 3",IF(Model!E46>=$B7,"Year 4",IF(Model!F46>=$B7,"Year 5","Later"))))) -> Year 4 | F7: ~130x today's network (docs/model_a2_results.md)

Sheet Assumptions
A1: Assumptions
A3: Market context (sourced; not used in formulas)
A4: Item | B4: Value | G4: Source
A5: US veterinary practices | B5: 34000 | G5: AVMA 2025 Economic State of the Profession, via dvm360 (2022 count): https://www.dvm360.com/view/2025-economic-state-of-the-veterinary-profession-trends-and-opportunities-for-your-practice
A6: Share of practices owned by corporate groups | B6: 0.3 | G6: Same source: corporate groups own ~30% of US practices and over half of companion-animal revenue
A7: US households owning a pet (millions) | B7: 95 | G7: APPA, 2025: https://americanpetproducts.org/news/u.s.-pet-industry-reaches-158-billion-in-2025-poised-for-continued-growth-in-2026
A8: US pet industry spending, 2025 ($bn) | B8: 158 | G8: APPA, 2025 (same link)
A10: Scenarios
A11: Scenario | B11: Partner ramp × | C11: Price × | G11: Note
A12: Low | B12: 0.6 | C12: 0.8 | G12: Multipliers applied to the base partner ramp and to every price
A13: Base | B13: 1 | C13: 1
A14: High | B14: 1.3 | C14: 1.15
A16: Partner network (clinics sharing data, end of year)
A17: Item | B17: Year 1 | C17: Year 2 | D17: Year 3 | E17: Year 4 | F17: Year 5 | G17: Note
A18: Partner clinics, base case | B18: 25 | C18: 120 | D18: 400 | E18: 900 | F18: 1500 | G18: Today's simulated network = 9 clinics. 1,500 clinics is about 4% of US practices
A20: Revenue assumptions (illustrative)
A21: Item | B21: Value | G21: Basis
A22: Premium scorecard price ($ per clinic per year) | B22: 1800 | G22: Embedded analytics: group benchmarking beyond the free partner scorecard
A23: Share of partner clinics buying premium scorecards | B23: 0.4 | G23: Assumption
A24: Research report average price ($) | B24: 40000 | G24: Research & insights (e.g., oral health report)
A25: Data-license annual contract value ($) | B25: 120000 | G25: Data products: de-identified cohort, Health Index, resistance feed
A26: Minimum partner clinics before data licenses are sold | B26: 100 | G26: Privacy: at 9 clinics 8% of pets cannot be released; more partners shrink suppression
A27: Scoring/API contract value ($ per client per year) | B27: 80000 | G27: Commercial models: drug-signal, demand-forecast scoring
A28: Signal-validation study price ($ per study) | B28: 250000 | G28: EHR cohort study for a manufacturer or regulator
A29: Clinics needed for common side-effect studies | B29: 720 | G29: From Model A2: ~80x today's 9-clinic network (docs/model_a2_results.md)
A30: Clinics needed for rare side-effect studies | B30: 1170 | G30: From Model A2: ~130x today's 9-clinic network
A32: Volume by year | B32: Year 1 | C32: Year 2 | D32: Year 3 | E32: Year 4 | F32: Year 5 | G32: Note
A33: Research reports sold | B33: 2 | C33: 4 | D33: 6 | E33: 8 | F33: 10
A34: Data licensees | B34: 0 | C34: 2 | D34: 4 | E34: 6 | F34: 8 | G34: Sold only once the license gate is met
A35: Scoring/API clients | B35: 0 | C35: 1 | D35: 3 | E35: 5 | F35: 7
A36: Common side-effect studies (if gate met) | B36: 0 | C36: 1 | D36: 2 | E36: 2 | F36: 3
A37: Rare side-effect studies (if gate met) | B37: 0 | C37: 0 | D37: 1 | E37: 1 | F37: 2
A39: Cost assumptions (illustrative)
A40: Item | B40: Value | G40: Basis
A41: Partner data incentive ($ per clinic per year) | B41: 1000 | G41: Free scorecards, integration support or rebates
A42: Loaded cost per employee ($ per year) | B42: 200000
A43: Infrastructure, fixed ($ per year) | B43: 60000
A44: Infrastructure per partner clinic ($ per year) | B44: 50
A45: Study delivery cost (% of study revenue) | B45: 0.4 | G45: Clinical review, outcome annotation, reporting
A47: Headcount by year | B47: Year 1 | C47: Year 2 | D47: Year 3 | E47: Year 4 | F47: Year 5 | G47: Note
...

Sheet Model
A1: Five-year model by scenario ($)
A2: All cells are formulas driven by the Assumptions sheet.
A4: Low scenario
A5: Line | B5: Year 1 | C5: Year 2 | D5: Year 3 | E5: Year 4 | F5: Year 5
A6: Partner clinics | B6: =ROUND(Assumptions!B$18*Assumptions!$B$12,0) -> 15 | C6: =ROUND(Assumptions!C$18*Assumptions!$B$12,0) -> 72 | D6: =ROUND(Assumptions!D$18*Assumptions!$B$12,0) -> 240 | E6: =ROUND(Assumptions!E$18*Assumptions!$B$12,0) -> 540 | F6: =ROUND(Assumptions!F$18*Assumptions!$B$12,0) -> 900
A7: Embedded analytics: premium scorecards | B7: =B6*Assumptions!$B$23*Assumptions!$B$22*Assumptions!$C$12 -> 8640 | C7: =C6*Assumptions!$B$23*Assumptions!$B$22*Assumptions!$C$12 -> 41472 | D7: =D6*Assumptions!$B$23*Assumptions!$B$22*Assumptions!$C$12 -> 138240 | E7: =E6*Assumptions!$B$23*Assumptions!$B$22*Assumptions!$C$12 -> 311040 | F7: =F6*Assumptions!$B$23*Assumptions!$B$22*Assumptions!$C$12 -> 518400
A8: Research and insights: reports | B8: =Assumptions!B$33*Assumptions!$B$24*Assumptions!$C$12 -> 64000 | C8: =Assumptions!C$33*Assumptions!$B$24*Assumptions!$C$12 -> 128000 | D8: =Assumptions!D$33*Assumptions!$B$24*Assumptions!$C$12 -> 192000 | E8: =Assumptions!E$33*Assumptions!$B$24*Assumptions!$C$12 -> 256000 | F8: =Assumptions!F$33*Assumptions!$B$24*Assumptions!$C$12 -> 320000
A9: Data products: licenses | B9: =IF(B6>=Assumptions!$B$26,Assumptions!B$34*Assumptions!$B$25*Assumptions!$C$12,0) -> 0 | C9: =IF(C6>=Assumptions!$B$26,Assumptions!C$34*Assumptions!$B$25*Assumptions!$C$12,0) -> 0 | D9: =IF(D6>=Assumptions!$B$26,Assumptions!D$34*Assumptions!$B$25*Assumptions!$C$12,0) -> 384000 | E9: =IF(E6>=Assumptions!$B$26,Assumptions!E$34*Assumptions!$B$25*Assumptions!$C$12,0) -> 576000 | F9: =IF(F6>=Assumptions!$B$26,Assumptions!F$34*Assumptions!$B$25*Assumptions!$C$12,0) -> 768000
A10: Commercial models: scoring/API contracts | B10: =Assumptions!B$35*Assumptions!$B$27*Assumptions!$C$12 -> 0 | C10: =Assumptions!C$35*Assumptions!$B$27*Assumptions!$C$12 -> 64000 | D10: =Assumptions!D$35*Assumptions!$B$27*Assumptions!$C$12 -> 192000 | E10: =Assumptions!E$35*Assumptions!$B$27*Assumptions!$C$12 -> 320000 | F10: =Assumptions!F$35*Assumptions!$B$27*Assumptions!$C$12 -> 448000
A11: Signal-validation studies, common side effects | B11: =IF(B6>=Assumptions!$B$29,Assumptions!B$36*Assumptions!$B$28*Assumptions!$C$12,0) -> 0 | C11: =IF(C6>=Assumptions!$B$29,Assumptions!C$36*Assumptions!$B$28*Assumptions!$C$12,0) -> 0 | D11: =IF(D6>=Assumptions!$B$29,Assumptions!D$36*Assumptions!$B$28*Assumptions!$C$12,0) -> 0 | E11: =IF(E6>=Assumptions!$B$29,Assumptions!E$36*Assumptions!$B$28*Assumptions!$C$12,0) -> 0 | F11: =IF(F6>=Assumptions!$B$29,Assumptions!F$36*Assumptions!$B$28*Assumptions!$C$12,0) -> 600000
A12: Signal-validation studies, rare side effects | B12: =IF(B6>=Assumptions!$B$30,Assumptions!B$37*Assumptions!$B$28*Assumptions!$C$12,0) -> 0 | C12: =IF(C6>=Assumptions!$B$30,Assumptions!C$37*Assumptions!$B$28*Assumptions!$C$12,0) -> 0 | D12: =IF(D6>=Assumptions!$B$30,Assumptions!D$37*Assumptions!$B$28*Assumptions!$C$12,0) -> 0 | E12: =IF(E6>=Assumptions!$B$30,Assumptions!E$37*Assumptions!$B$28*Assumptions!$C$12,0) -> 0 | F12: =IF(F6>=Assumptions!$B$30,Assumptions!F$37*Assumptions!$B$28*Assumptions!$C$12,0) -> 0
A13: Total revenue | B13: =SUM(B7:B12) -> 72640 | C13: =SUM(C7:C12) -> 233472 | D13: =SUM(D7:D12) -> 906240 | E13: =SUM(E7:E12) -> 1463040 | F13: =SUM(F7:F12) -> 2654400
A14: Partner data incentives | B14: =B6*Assumptions!$B$41 -> 15000 | C14: =C6*Assumptions!$B$41 -> 72000 | D14: =D6*Assumptions!$B$41 -> 240000 | E14: =E6*Assumptions!$B$41 -> 540000 | F14: =F6*Assumptions!$B$41 -> 900000
A15: Team | B15: =Assumptions!B$48*Assumptions!$B$42 -> 800000 | C15: =Assumptions!C$48*Assumptions!$B$42 -> 1400000 | D15: =Assumptions!D$48*Assumptions!$B$42 -> 2000000 | E15: =Assumptions!E$48*Assumptions!$B$42 -> 2600000 | F15: =Assumptions!F$48*Assumptions!$B$42 -> 3000000
A16: Infrastructure | B16: =Assumptions!$B$43+B6*Assumptions!$B$44 -> 60750 | C16: =Assumptions!$B$43+C6*Assumptions!$B$44 -> 63600 | D16: =Assumptions!$B$43+D6*Assumptions!$B$44 -> 72000 | E16: =Assumptions!$B$43+E6*Assumptions!$B$44 -> 87000 | F16: =Assumptions!$B$43+F6*Assumptions!$B$44 -> 105000
A17: Study delivery | B17: =(B11+B12)*Assumptions!$B$45 -> 0 | C17: =(C11+C12)*Assumptions!$B$45 -> 0 | D17: =(D11+D12)*Assumptions!$B$45 -> 0 | E17: =(E11+E12)*Assumptions!$B$45 -> 0 | F17: =(F11+F12)*Assumptions!$B$45 -> 240000
A18: Total costs | B18: =SUM(B14:B17) -> 875750 | C18: =SUM(C14:C17) -> 1535600 | D18: =SUM(D14:D17) -> 2312000 | E18: =SUM(E14:E17) -> 3227000 | F18: =SUM(F14:F17) -> 4245000
A19: EBITDA | B19: =B13-B18 -> -803110 | C19: =C13-C18 -> -1302128 | D19: =D13-D18 -> -1405760 | E19: =E13-E18 -> -1763960 | F19: =F13-F18 -> -1590600
A20: EBITDA margin | B20: =IF(B13=0,0,B19/B13) -> -11.05603 | C20: =IF(C13=0,0,C19/C13) -> -5.5772341 | D20: =IF(D13=0,0,D19/D13) -> -1.5512006 | E20: =IF(E13=0,0,E19/E13) -> -1.2056813 | F20: =IF(F13=0,0,F19/F13) -> -0.59923146
A21: Cumulative EBITDA | B21: =B19 -> -803110 | C21: =B21+C19 -> -2105238 | D21: =C21+D19 -> -3510998 | E21: =D21+E19 -> -5274958 | F21: =E21+F19 -> -6865558
A22: Helper: year number if EBITDA positive (else 99) | B22: =IF(B19>0,1,99) -> 99 | C22: =IF(C19>0,2,99) -> 99 | D22: =IF(D19>0,3,99) -> 99 | E22: =IF(E19>0,4,99) -> 99 | F22: =IF(F19>0,5,99) -> 99
A24: Base scenario
A25: Line | B25: Year 1 | C25: Year 2 | D25: Year 3 | E25: Year 4 | F25: Year 5
A26: Partner clinics | B26: =ROUND(Assumptions!B$18*Assumptions!$B$13,0) -> 25 | C26: =ROUND(Assumptions!C$18*Assumptions!$B$13,0) -> 120 | D26: =ROUND(Assumptions!D$18*Assumptions!$B$13,0) -> 400 | E26: =ROUND(Assumptions!E$18*Assumptions!$B$13,0) -> 900 | F26: =ROUND(Assumptions!F$18*Assumptions!$B$13,0) -> 1500
A27: Embedded analytics: premium scorecards | B27: =B26*Assumptions!$B$23*Assumptions!$B$22*Assumptions!$C$13 -> 18000 | C27: =C26*Assumptions!$B$23*Assumptions!$B$22*Assumptions!$C$13 -> 86400 | D27: =D26*Assumptions!$B$23*Assumptions!$B$22*Assumptions!$C$13 -> 288000 | E27: =E26*Assumptions!$B$23*Assumptions!$B$22*Assumptions!$C$13 -> 648000 | F27: =F26*Assumptions!$B$23*Assumptions!$B$22*Assumptions!$C$13 -> 1080000
A28: Research and insights: reports | B28: =Assumptions!B$33*Assumptions!$B$24*Assumptions!$C$13 -> 80000 | C28: =Assumptions!C$33*Assumptions!$B$24*Assumptions!$C$13 -> 160000 | D28: =Assumptions!D$33*Assumptions!$B$24*Assumptions!$C$13 -> 240000 | E28: =Assumptions!E$33*Assumptions!$B$24*Assumptions!$C$13 -> 320000 | F28: =Assumptions!F$33*Assumptions!$B$24*Assumptions!$C$13 -> 400000
A29: Data products: licenses | B29: =IF(B26>=Assumptions!$B$26,Assumptions!B$34*Assumptions!$B$25*Assumptions!$C$13,0) -> 0 | C29: =IF(C26>=Assumptions!$B$26,Assumptions!C$34*Assumptions!$B$25*Assumptions!$C$13,0) -> 240000 | D29: =IF(D26>=Assumptions!$B$26,Assumptions!D$34*Assumptions!$B$25*Assumptions!$C$13,0) -> 480000 | E29: =IF(E26>=Assumptions!$B$26,Assumptions!E$34*Assumptions!$B$25*Assumptions!$C$13,0) -> 720000 | F29: =IF(F26>=Assumptions!$B$26,Assumptions!F$34*Assumptions!$B$25*Assumptions!$C$13,0) -> 960000
A30: Commercial models: scoring/API contracts | B30: =Assumptions!B$35*Assumptions!$B$27*Assumptions!$C$13 -> 0 | C30: =Assumptions!C$35*Assumptions!$B$27*Assumptions!$C$13 -> 80000 | D30: =Assumptions!D$35*Assumptions!$B$27*Assumptions!$C$13 -> 240000 | E30: =Assumptions!E$35*Assumptions!$B$27*Assumptions!$C$13 -> 400000 | F30: =Assumptions!F$35*Assumptions!$B$27*Assumptions!$C$13 -> 560000
A31: Signal-validation studies, common side effects | B31: =IF(B26>=Assumptions!$B$29,Assumptions!B$36*Assumptions!$B$28*Assumptions!$C$13,0) -> 0 | C31: =IF(C26>=Assumptions!$B$29,Assumptions!C$36*Assumptions!$B$28*Assumptions!$C$13,0) -> 0 | D31: =IF(D26>=Assumptions!$B$29,Assumptions!D$36*Assumptions!$B$28*Assumptions!$C$13,0) -> 0 | E31: =IF(E26>=Assumptions!$B$29,Assumptions!E$36*Assumptions!$B$28*Assumptions!$C$13,0) -> 500000 | F31: =IF(F26>=Assumptions!$B$29,Assumptions!F$36*Assumptions!$B$28*Assumptions!$C$13,0) -> 750000
A32: Signal-validation studies, rare side effects | B32: =IF(B26>=Assumptions!$B$30,Assumptions!B$37*Assumptions!$B$28*Assumptions!$C$13,0) -> 0 | C32: =IF(C26>=Assumptions!$B$30,Assumptions!C$37*Assumptions!$B$28*Assumptions!$C$13,0) -> 0 | D32: =IF(D26>=Assumptions!$B$30,Assumptions!D$37*Assumptions!$B$28*Assumptions!$C$13,0) -> 0 | E32: =IF(E26>=Assumptions!$B$30,Assumptions!E$37*Assumptions!$B$28*Assumptions!$C$13,0) -> 0 | F32: =IF(F26>=Assumptions!$B$30,Assumptions!F$37*Assumptions!$B$28*Assumptions!$C$13,0) -> 500000
A33: Total revenue | B33: =SUM(B27:B32) -> 98000 | C33: =SUM(C27:C32) -> 566400 | D33: =SUM(D27:D32) -> 1248000 | E33: =SUM(E27:E32) -> 2588000 | F33: =SUM(F27:F32) -> 4250000
A34: Partner data incentives | B34: =B26*Assumptions!$B$41 -> 25000 | C34: =C26*Assumptions!$B$41 -> 120000 | D34: =D26*Assumptions!$B$41 -> 400000 | E34: =E26*Assumptions!$B$41 -> 900000 | F34: =F26*Assumptions!$B$41 -> 1500000
A35: Team | B35: =Assumptions!B$48*Assumptions!$B$42 -> 800000 | C35: =Assumptions!C$48*Assumptions!$B$42 -> 1400000 | D35: =Assumptions!D$48*Assumptions!$B$42 -> 2000000 | E35: =Assumptions!E$48*Assumptions!$B$42 -> 2600000 | F35: =Assumptions!F$48*Assumptions!$B$42 -> 3000000
A36: Infrastructure | B36: =Assumptions!$B$43+B26*Assumptions!$B$44 -> 61250 | C36: =Assumptions!$B$43+C26*Assumptions!$B$44 -> 66000 | D36: =Assumptions!$B$43+D26*Assumptions!$B$44 -> 80000 | E36: =Assumptions!$B$43+E26*Assumptions!$B$44 -> 105000 | F36: =Assumptions!$B$43+F26*Assumptions!$B$44 -> 135000
A37: Study delivery | B37: =(B31+B32)*Assumptions!$B$45 -> 0 | C37: =(C31+C32)*Assumptions!$B$45 -> 0 | D37: =(D31+D32)*Assumptions!$B$45 -> 0 | E37: =(E31+E32)*Assumptions!$B$45 -> 200000 | F37: =(F31+F32)*Assumptions!$B$45 -> 500000
A38: Total costs | B38: =SUM(B34:B37) -> 886250 | C38: =SUM(C34:C37) -> 1586000 | D38: =SUM(D34:D37) -> 2480000 | E38: =SUM(E34:E37) -> 3805000 | F38: =SUM(F34:F37) -> 5135000
A39: EBITDA | B39: =B33-B38 -> -788250 | C39: =C33-C38 -> -1019600 | D39: =D33-D38 -> -1232000 | E39: =E33-E38 -> -1217000 | F39: =F33-F38 -> -885000
A40: EBITDA margin | B40: =IF(B33=0,0,B39/B33) -> -8.0433673 | C40: =IF(C33=0,0,C39/C33) -> -1.8001412 | D40: =IF(D33=0,0,D39/D33) -> -0.98717949 | E40: =IF(E33=0,0,E39/E33) -> -0.4702473 | F40: =IF(F33=0,0,F39/F33) -> -0.20823529
A41: Cumulative EBITDA | B41: =B39 -> -788250 | C41: =B41+C39 -> -1807850 | D41: =C41+D39 -> -3039850 | E41: =D41+E39 -> -4256850 | F41: =E41+F39 -> -5141850
A42: Helper: year number if EBITDA positive (else 99) | B42: =IF(B39>0,1,99) -> 99 | C42: =IF(C39>0,2,99) -> 99 | D42: =IF(D39>0,3,99) -> 99 | E42: =IF(E39>0,4,99) -> 99 | F42: =IF(F39>0,5,99) -> 99
...
